Workbook

Sheet Raw_Data
A1: customer_id | B1: age | C1: gender | D1: country | E1: avg_order_value | F1: total_orders | G1: last_purchase | H1: is_fraudulent | I1: preferred_category | J1: email_open_rate | K1: customer_since | L1: loyalty_score | M1: churn_risk
A2: CUST_8270 | B2: 30 | C2: Female | D2: Brazil | E2: 101.08 | F2: 8 | G2: 176 | H2: 1 | I2: Beauty | J2: 25.6 | K2: 45448 | L2: 50 | M2: 0.2
A3: CUST_1860 | B3: 53 | C3: Female | D3: USA | E3: 90.39 | F3: 10 | G3: 88 | H3: 0 | I3: Electronics | J3: 12.3 | K3: 45341 | L3: 37 | M3: 0.34
A4: CUST_6390 | B4: 73 | C4: Male | D4: Australia | E4: 83.28 | F4: 6 | G4: 203 | H4: 0 | I4: Sports | K4: 45398 | L4: 65 | M4: 0.05
A5: CUST_6191 | B5: 30 | C5: Other | D5: Japan | E5: 109.9 | F5: 9 | G5: 346 | H5: 1 | I5: Electronics | J5: 42.9 | K5: 44020 | L5: 93 | M5: 0.19
A6: CUST_6734 | B6: 29 | C6: Female | D6: Canada | E6: 269.38 | F6: 16 | G6: 342 | H6: 0 | I6: Fashion | J6: 5.3 | K6: 45756 | L6: 79 | M6: 0.15
A7: CUST_7265 | B7: 54 | C7: Male | D7: Canada | E7: 114.31 | F7: 11 | G7: 210 | H7: 0 | I7: Beauty | J7: 56.5 | K7: 44471 | L7: 44 | M7: 0.21
A8: CUST_1466 | B8: 27 | C8: Female | D8: Canada | E8: 34.03 | F8: 7 | G8: 212 | H8: 0 | I8: Electronics | J8: 0.2 | K8: 44549 | L8: 60 | M8: 0.39
A9: CUST_5426 | B9: 77 | C9: Female | D9: Brazil | E9: 171.25 | F9: 9 | G9: 20 | H9: 0 | I9: Electronics | J9: 15.1 | K9: 44236 | L9: 29 | M9: 0.24
A10: CUST_6578 | B10: 73 | C10: Female | D10: Australia | E10: 116.79 | F10: 10 | G10: 87 | H10: 0 | I10: Sports | J10: 14.7 | K10: 44076 | L10: 85 | M10: 0.37
A11: CUST_9322 | B11: 26 | C11: Male | D11: France | E11: 55.93 | F11: 4 | G11: 12 | H11: 0 | I11: Fashion | J11: 68.8 | K11: 45347 | L11: 63 | M11: 0.52
A12: CUST_2685 | B12: 69 | C12: Female | D12: India | E12: 128.78 | F12: 7 | G12: 119 | H12: 0 | I12: Fashion | J12: 48.6 | K12: 45571 | L12: 76 | M12: 0.11
A13: CUST_1769 | B13: 24 | C13: Female | D13: Canada | E13: 88.23 | F13: 14 | G13: 177 | H13: 0 | I13: Beauty | J13: 83.6 | K13: 45417 | L13: 26 | M13: 0.12
A14: CUST_7949 | B14: 19 | C14: Male | D14: India | E14: 77.24 | F14: 12 | G14: 128 | H14: 0 | I14: Home | J14: 26.5 | K14: 44375 | L14: 45 | M14: 0.63
A15: CUST_3433 | B15: 71 | C15: Female | D15: Brazil | E15: 91.39 | F15: 8 | G15: 50 | H15: 0 | I15: Home | J15: 21.1 | K15: 44757 | L15: 95 | M15: 0.34
A16: CUST_6311 | B16: 73 | C16: Female | D16: India | E16: 131.23 | F16: 7 | G16: 41 | H16: 0 | I16: Sports | J16: 80.3 | K16: 45433 | L16: 35 | M16: 0.61
... A31: CUST_5658 | B31: 42 | C31: Male | D31: Brazil | E31: 61.94 | F31: 8 | G31: 17 | H31: 0 | I31: Beauty | J31: 99 | K31: 44457 | L31: 49 | M31: 0.41
A32: CUST_2899 | B32: 48 | C32: Female | D32: Canada | F32: 8 | G32: 200 | H32: 0 | I32: Home | J32: 43.3 | K32: 44924 | L32: 3 | M32: 0.27
A33: CUST_8734 | B33: 67 | C33: Male | D33: Australia | E33: 109.18 | F33: 11 | G33: 252 | H33: 0 | I33: Sports | J33: 58.6 | K33: 44429 | L33: 17 | M33: 0.31
A34: CUST_2267 | B34: 37 | C34: Male | D34: Australia | E34: 75.98 | F34: 6 | G34: 191 | H34: 0 | I34: Beauty | J34: 59.4 | K34: 44202 | L34: 25 | M34: 0.22
A35: CUST_2528 | B35: 61 | C35: Female | D35: France | E35: 46.66 | F35: 7 | G35: 48 | H35: 0 | I35: Home | J35: 34.6 | K35: 45282 | L35: 94 | M35: 0.34
A36: CUST_4556 | B36: 72 | C36: Female | D36: China | E36: 106.23 | F36: 13 | G36: 93 | H36: 0 | I36: Sports | J36: 54.5 | K36: 45209 | L36: 14 | M36: 0.25
A37: CUST_4890 | B37: 34 | C37: Male | D37: Germany | E37: 112.56 | F37: 13 | G37: 236 | H37: 0 | I37: Beauty | J37: 58.3 | K37: 44471 | L37: 93 | M37: 0.28
A38: CUST_9838 | B38: 62 | C38: Other | D38: China | E38: 175.73 | F38: 14 | G38: 221 | H38: 0 | I38: Fashion | J38: 76.1 | K38: 44501 | L38: 5 | M38: 0.33
A39: CUST_6393 | B39: 19 | C39: Female | D39: Canada | E39: 22.72 | F39: 12 | G39: 166 | H39: 0 | I39: Sports | J39: 66.2 | K39: 45462 | L39: 71 | M39: 0.05
A40: CUST_9792 | B40: 42 | C40: Male | D40: Canada | E40: 103.97 | F40: 13 | G40: 253 | H40: 0 | I40: Beauty | J40: 44.7 | K40: 45611 | L40: 83 | M40: 0.09
A41: CUST_9433 | B41: 30 | C41: Female | D41: USA | E41: 43.35 | F41: 13 | G41: 56 | H41: 0 | I41: Electronics | J41: 19.1 | K41: 45682 | L41: 33 | M41: 0.08
A42: CUST_8513 | B42: 75 | C42: Female | D42: Australia | E42: 48.94 | F42: 11 | G42: 5 | H42: 0 | I42: Fashion | J42: 2.5 | K42: 44609 | L42: 85 | M42: 0.14
A43: CUST_3612 | B43: 56 | C43: Female | D43: UK | E43: 53.17 | F43: 5 | G43: 237 | H43: 0 | I43: Sports | J43: 65.2 | K43: 45023 | L43: 51 | M43: 0.09
A44: CUST_8041 | B44: 45 | C44: Female | D44: Japan | E44: 26.94 | F44: 10 | G44: 220 | H44: 0 | I44: Home | J44: 47.8 | K44: 45673 | L44: 85 | M44: 0.38
... A54: CUST_4073 | B54: 37 | C54: Male | D54: Canada | E54: 99.86 | F54: 13 | G54: 209 | H54: 0 | I54: Fashion | J54: 96.7 | K54: 45832 | L54: 34 | M54: 0.24
A55: CUST_2021 | B55: 22 | C55: Female | D55: USA | F55: 9 | G55: 255 | H55: 0 | I55: Home | J55: 36.5 | K55: 44545 | L55: 65 | M55: 0.13
A56: CUST_4843 | B56: 36 | C56: Male | D56: Canada | E56: 50.6 | F56: 11 | G56: 311 | H56: 0 | I56: Beauty | J56: 79.2 | K56: 44830 | L56: 32 | M56: 0.36
A57: CUST_8989 | B57: 39 | C57: Other | D57: UK | E57: 64.39 | F57: 10 | G57: 39 | H57: 0 | I57: Beauty | J57: 24.2 | K57: 44751 | L57: 22 | M57: 0.4
A58: CUST_7873 | B58: 76 | C58: Male | D58: France | E58: 188.66 | F58: 19 | G58: 352 | H58: 0 | I58: Home | J58: 5.8 | K58: 45411 | L58: 62 | M58: 0.33
A59: CUST_6675 | B59: 77 | C59: Male | D59: Canada | E59: 142.52 | F59: 10 | G59: 201 | H59: 0 | I59: Home | J59: 4 | K59: 44389 | L59: 93 | M59: 0.31
A60: CUST_1161 | B60: 36 | C60: Male | D60: Japan | F60: 12 | G60: 85 | H60: 0 | I60: Beauty | J60: 2.9 | K60: 44979 | L60: 45 | M60: 0.35
A61: CUST_5297 | B61: 79 | C61: Male | D61: Canada | E61: 78.1 | F61: 16 | G61: 42 | H61: 0 | I61: Sports | J61: 73.6 | K61: 45545 | L61: 11 | M61: 0.17
A62: CUST_1995 | B62: 64 | C62: Female | D62: France | E62: 29.96 | F62: 10 | G62: 235 | H62: 0 | I62: Electronics | J62: 34.2 | K62: 45082 | L62: 33 | M62: 0.38
A63: CUST_8629 | B63: 79 | C63: Female | D63: China | E63: 25.66 | F63: 12 | G63: 69 | H63: 0 | I63: Beauty | J63: 82.4 | K63: 44301 | L63: 38 | M63: 0.33
...

Sheet Cleaned_Data
A1: customer_id | B1: age | C1: gender | D1: country | E1: avg_order_value | F1: total_orders | G1: last_purchase | H1: is_fraudulent | I1: preferred_category | J1: email_open_rate | K1: customer_since | L1: loyalty_score | M1: churn_risk | N1: avg_order_value_clean | O1: email_open_rate_clean | P1: customer_record_count | Q1: estimated_customer_value | R1: recency_segment | S1: churn_risk_segment | T1: age_group | U1: customer_tenure_days | V1: loyalty_segment | W1: fraud_status | X1: customer_value_segment | Y1: customer_priority | Z1: data_quality_flag
A2: CUST_8270 | B2: 30 | C2: Female | D2: Brazil | E2: 101.08 | F2: 8 | G2: 176 | H2: 1 | I2: Beauty | J2: 25.6 | K2: 45448 | L2: 50 | M2: 0.2 | N2: =IF(E2="",Data_Validation!$B$1,E2) -> 101.08 | O2: =IF(J2="",Data_Validation!$B$2,J2) -> 25.6 | P2: =COUNTIF($A$2:$A$5001,A2) -> 1 | Q2: =CustomerData[[#This Row],[avg_order_value_clean]]*CustomerData[[#This Row],[total_orders]] -> 808.64 | R2: =IF(G2<=30,"Active",IF(G2<=90,"At Risk","Inactive")) -> Inactive | S2: =IF(M2<0.2,"Low Risk",IF(M2<0.5,"Medium Risk","High Risk")) -> Medium Risk | T2: =IF(B2<25,"Under 25",IF(B2<35,"25-34",IF(B2<45,"35-44",IF(B2<55,"45-54","55+")))) -> 25-34 | U2: =TODAY()-K2 -> 813 | V2: =IF(L2<40,"Low Loyalty",IF(L2<70,"Medium Loyalty","High Loyalty")) -> Medium Loyalty | W2: =IF(H2=1,"Fraudulent","Legitimate") -> Fraudulent | X2: =IF(Q2<Data_Validation!$B$8,"Low Value",IF(Q2<Data_Validation!$B$9,"Medium Value","High Value")) -> Low Value | Y2: =IF(AND(X2="High Value",S2="High Risk"),"Critical - Retain",IF(AND(X2="High Value",S2<>"High Risk"),"High Value - Maintain",IF(AND(X2<>"High Value",S2="High Risk"),"At Risk - Develop","Stable"))) -> Stable | Z2: =IF(OR(B2<18,F2<0,N2<0,O2<0,O2>1,M2<0,M2>1),"Check Data","Valid") -> Check Data
A3: CUST_1860 | B3: 53 | C3: Female | D3: USA | E3: 90.39 | F3: 10 | G3: 88 | H3: 0 | I3: Electronics | J3: 12.3 | K3: 45341 | L3: 37 | M3: 0.34 | N3: =IF(E3="",Data_Validation!$B$1,E3) -> 90.39 | O3: =IF(J3="",Data_Validation!$B$2,J3) -> 12.3 | P3: =COUNTIF($A$2:$A$5001,A3) -> 1 | Q3: =CustomerData[[#This Row],[avg_order_value_clean]]*CustomerData[[#This Row],[total_orders]] -> 903.9 | R3: =IF(G3<=30,"Active",IF(G3<=90,"At Risk","Inactive")) -> At Risk | S3: =IF(M3<0.2,"Low Risk",IF(M3<0.5,"Medium Risk","High Risk")) -> Medium Risk | T3: =IF(B3<25,"Under 25",IF(B3<35,"25-34",IF(B3<45,"35-44",IF(B3<55,"45-54","55+")))) -> 45-54 | U3: =TODAY()-K3 -> 920 | V3: =IF(L3<40,"Low Loyalty",IF(L3<70,"Medium Loyalty","High Loyalty")) -> Low Loyalty | W3: =IF(H3=1,"Fraudulent","Legitimate") -> Legitimate | X3: =IF(Q3<Data_Validation!$B$8,"Low Value",IF(Q3<Data_Validation!$B$9,"Medium Value","High Value")) -> Low Value | Y3: =IF(AND(X3="High Value",S3="High Risk"),"Critical - Retain",IF(AND(X3="High Value",S3<>"High Risk"),"High Value - Maintain",IF(AND(X3<>"High Value",S3="High Risk"),"At Risk - Develop","Stable"))) -> Stable | Z3: =IF(OR(B3<18,F3<0,N3<0,O3<0,O3>1,M3<0,M3>1),"Check Data","Valid") -> Check Data
A4: CUST_6390 | B4: 73 | C4: Male | D4: Australia | E4: 83.28 | F4: 6 | G4: 203 | H4: 0 | I4: Sports | K4: 45398 | L4: 65 | M4: 0.05 | N4: =IF(E4="",Data_Validation!$B$1,E4) -> 83.28 | O4: =IF(J4="",Data_Validation!$B$2,J4) -> 250 | P4: =COUNTIF($A$2:$A$5001,A4) -> 2 | Q4: =CustomerData[[#This Row],[avg_order_value_clean]]*CustomerData[[#This Row],[total_orders]] -> 499.68 | R4: =IF(G4<=30,"Active",IF(G4<=90,"At Risk","Inactive")) -> Inactive | S4: =IF(M4<0.2,"Low Risk",IF(M4<0.5,"Medium Risk","High Risk")) -> Low Risk | T4: =IF(B4<25,"Under 25",IF(B4<35,"25-34",IF(B4<45,"35-44",IF(B4<55,"45-54","55+")))) -> 55+ | U4: =TODAY()-K4 -> 863 | V4: =IF(L4<40,"Low Loyalty",IF(L4<70,"Medium Loyalty","High Loyalty")) -> Medium Loyalty | W4: =IF(H4=1,"Fraudulent","Legitimate") -> Legitimate | X4: =IF(Q4<Data_Validation!$B$8,"Low Value",IF(Q4<Data_Validation!$B$9,"Medium Value","High Value")) -> Low Value | Y4: =IF(AND(X4="High Value",S4="High Risk"),"Critical - Retain",IF(AND(X4="High Value",S4<>"High Risk"),"High Value - Maintain",IF(AND(X4<>"High Value",S4="High Risk"),"At Risk - Develop","Stable"))) -> Stable | Z4: =IF(OR(B4<18,F4<0,N4<0,O4<0,O4>1,M4<0,M4>1),"Check Data","Valid") -> Check Data
A5: CUST_6191 | B5: 30 | C5: Other | D5: Japan | E5: 109.9 | F5: 9 | G5: 346 | H5: 1 | I5: Electronics | J5: 42.9 | K5: 44020 | L5: 93 | M5: 0.19 | N5: =IF(E5="",Data_Validation!$B$1,E5) -> 109.9 | O5: =IF(J5="",Data_Validation!$B$2,J5) -> 42.9 | P5: =COUNTIF($A$2:$A$5001,A5) -> 1 | Q5: =CustomerData[[#This Row],[avg_order_value_clean]]*CustomerData[[#This Row],[total_orders]] -> 989.1 | R5: =IF(G5<=30,"Active",IF(G5<=90,"At Risk","Inactive")) -> Inactive | S5: =IF(M5<0.2,"Low Risk",IF(M5<0.5,"Medium Risk","High Risk")) -> Low Risk | T5: =IF(B5<25,"Under 25",IF(B5<35,"25-34",IF(B5<45,"35-44",IF(B5<55,"45-54","55+")))) -> 25-34 | U5: =TODAY()-K5 -> 2241 | V5: =IF(L5<40,"Low Loyalty",IF(L5<70,"Medium Loyalty","High Loyalty")) -> High Loyalty | W5: =IF(H5=1,"Fraudulent","Legitimate") -> Fraudulent | X5: =IF(Q5<Data_Validation!$B$8,"Low Value",IF(Q5<Data_Validation!$B$9,"Medium Value","High Value")) -> Low Value | Y5: =IF(AND(X5="High Value",S5="High Risk"),"Critical - Retain",IF(AND(X5="High Value",S5<>"High Risk"),"High Value - Maintain",IF(AND(X5<>"High Value",S5="High Risk"),"At Risk - Develop","Stable"))) -> Stable | Z5: =IF(OR(B5<18,F5<0,N5<0,O5<0,O5>1,M5<0,M5>1),"Check Data","Valid") -> Check Data
A6: CUST_6734 | B6: 29 | C6: Female | D6: Canada | E6: 269.38 | F6: 16 | G6: 342 | H6: 0 | I6: Fashion | J6: 5.3 | K6: 45756 | L6: 79 | M6: 0.15 | N6: =IF(E6="",Data_Validation!$B$1,E6) -> 269.38 | O6: =IF(J6="",Data_Validation!$B$2,J6) -> 5.3 | P6: =COUNTIF($A$2:$A$5001,A6) -> 1 | Q6: =CustomerData[[#This Row],[avg_order_value_clean]]*CustomerData[[#This Row],[total_orders]] -> 4310.08 | R6: =IF(G6<=30,"Active",IF(G6<=90,"At Risk","Inactive")) -> Inactive | S6: =IF(M6<0.2,"Low Risk",IF(M6<0.5,"Medium Risk","High Risk")) -> Low Risk | T6: =IF(B6<25,"Under 25",IF(B6<35,"25-34",IF(B6<45,"35-44",IF(B6<55,"45-54","55+")))) -> 25-34 | U6: =TODAY()-K6 -> 505 | V6: =IF(L6<40,"Low Loyalty",IF(L6<70,"Medium Loyalty","High Loyalty")) -> High Loyalty | W6: =IF(H6=1,"Fraudulent","Legitimate") -> Legitimate | X6: =IF(Q6<Data_Validation!$B$8,"Low Value",IF(Q6<Data_Validation!$B$9,"Medium Value","High Value")) -> High Value | Y6: =IF(AND(X6="High Value",S6="High Risk"),"Critical - Retain",IF(AND(X6="High Value",S6<>"High Risk"),"High Value - Maintain",IF(AND(X6<>"High Value",S6="High Risk"),"At Risk - Develop","Stable"))) -> High Value - Maintain | Z6: =IF(OR(B6<18,F6<0,N6<0,O6<0,O6>1,M6<0,M6>1),"Check Data","Valid") -> Check Data
A7: CUST_7265 | B7: 54 | C7: Male | D7: Canada | E7: 114.31 | F7: 11 | G7: 210 | H7: 0 | I7: Beauty | J7: 56.5 | K7: 44471 | L7: 44 | M7: 0.21 | N7: =IF(E7="",Data_Validation!$B$1,E7) -> 114.31 | O7: =IF(J7="",Data_Validation!$B$2,J7) -> 56.5 | P7: =COUNTIF($A$2:$A$5001,A7) -> 2 | Q7: =CustomerData[[#This Row],[avg_order_value_clean]]*CustomerData[[#This Row],[total_orders]] -> 1257.41 | R7: =IF(G7<=30,"Active",IF(G7<=90,"At Risk","Inactive")) -> Inactive | S7: =IF(M7<0.2,"Low Risk",IF(M7<0.5,"Medium Risk","High Risk")) -> Medium Risk | T7: =IF(B7<25,"Under 25",IF(B7<35,"25-34",IF(B7<45,"35-44",IF(B7<55,"45-54","55+")))) -> 45-54 | U7: =TODAY()-K7 -> 1790 | V7: =IF(L7<40,"Low Loyalty",IF(L7<70,"Medium Loyalty","High Loyalty")) -> Medium Loyalty | W7: =IF(H7=1,"Fraudulent","Legitimate") -> Legitimate | X7: =IF(Q7<Data_Validation!$B$8,"Low Value",IF(Q7<Data_Validation!$B$9,"Medium Value","High Value")) -> Low Value | Y7: =IF(AND(X7="High Value",S7="High Risk"),"Critical - Retain",IF(AND(X7="High Value",S7<>"High Risk"),"High Value - Maintain",IF(AND(X7<>"High Value",S7="High Risk"),"At Risk - Develop","Stable"))) -> Stable | Z7: =IF(OR(B7<18,F7<0,N7<0,O7<0,O7>1,M7<0,M7>1),"Check Data","Valid") -> Check Data
A8: CUST_1466 | B8: 27 | C8: Female | D8: Canada | E8: 34.03 | F8: 7 | G8: 212 | H8: 0 | I8: Electronics | J8: 0.2 | K8: 44549 | L8: 60 | M8: 0.39 | N8: =IF(E8="",Data_Validation!$B$1,E8) -> 34.03 | O8: =IF(J8="",Data_Validation!$B$2,J8) -> 0.2 | P8: =COUNTIF($A$2:$A$5001,A8) -> 1 | Q8: =CustomerData[[#This Row],[avg_order_value_clean]]*CustomerData[[#This Row],[total_orders]] -> 238.21 | R8: =IF(G8<=30,"Active",IF(G8<=90,"At Risk","Inactive")) -> Inactive | S8: =IF(M8<0.2,"Low Risk",IF(M8<0.5,"Medium Risk","High Risk")) -> Medium Risk | T8: =IF(B8<25,"Under 25",IF(B8<35,"25-34",IF(B8<45,"35-44",IF(B8<55,"45-54","55+")))) -> 25-34 | U8: =TODAY()-K8 -> 1712 | V8: =IF(L8<40,"Low Loyalty",IF(L8<70,"Medium Loyalty","High Loyalty")) -> Medium Loyalty | W8: =IF(H8=1,"Fraudulent","Legitimate") -> Legitimate | X8: =IF(Q8<Data_Validation!$B$8,"Low Value",IF(Q8<Data_Validation!$B$9,"Medium Value","High Value")) -> Low Value | Y8: =IF(AND(X8="High Value",S8="High Risk"),"Critical - Retain",IF(AND(X8="High Value",S8<>"High Risk"),"High Value - Maintain",IF(AND(X8<>"High Value",S8="High Risk"),"At Risk - Develop","Stable"))) -> Stable | Z8: =IF(OR(B8<18,F8<0,N8<0,O8<0,O8>1,M8<0,M8>1),"Check Data","Valid") -> Valid
A9: CUST_5426 | B9: 77 | C9: Female | D9: Brazil | E9: 171.25 | F9: 9 | G9: 20 | H9: 0 | I9: Electronics | J9: 15.1 | K9: 44236 | L9: 29 | M9: 0.24 | N9: =IF(E9="",Data_Validation!$B$1,E9) -> 171.25 | O9: =IF(J9="",Data_Validation!$B$2,J9) -> 15.1 | P9: =COUNTIF($A$2:$A$5001,A9) -> 3 | Q9: =CustomerData[[#This Row],[avg_order_value_clean]]*CustomerData[[#This Row],[total_orders]] -> 1541.25 | R9: =IF(G9<=30,"Active",IF(G9<=90,"At Risk","Inactive")) -> Active | S9: =IF(M9<0.2,"Low Risk",IF(M9<0.5,"Medium Risk","High Risk")) -> Medium Risk | T9: =IF(B9<25,"Under 25",IF(B9<35,"25-34",IF(B9<45,"35-44",IF(B9<55,"45-54","55+")))) -> 55+ | U9: =TODAY()-K9 -> 2025 | V9: =IF(L9<40,"Low Loyalty",IF(L9<70,"Medium Loyalty","High Loyalty")) -> Low Loyalty | W9: =IF(H9=1,"Fraudulent","Legitimate") -> Legitimate | X9: =IF(Q9<Data_Validation!$B$8,"Low Value",IF(Q9<Data_Validation!$B$9,"Medium Value","High Value")) -> High Value | Y9: =IF(AND(X9="High Value",S9="High Risk"),"Critical - Retain",IF(AND(X9="High Value",S9<>"High Risk"),"High Value - Maintain",IF(AND(X9<>"High Value",S9="High Risk"),"At Risk - Develop","Stable"))) -> High Value - Maintain | Z9: =IF(OR(B9<18,F9<0,N9<0,O9<0,O9>1,M9<0,M9>1),"Check Data","Valid") -> Check Data
A10: CUST_6578 | B10: 73 | C10: Female | D10: Australia | E10: 116.79 | F10: 10 | G10: 87 | H10: 0 | I10: Sports | J10: 14.7 | K10: 44076 | L10: 85 | M10: 0.37 | N10: =IF(E10="",Data_Validation!$B$1,E10) -> 116.79 | O10: =IF(J10="",Data_Validation!$B$2,J10) -> 14.7 | P10: =COUNTIF($A$2:$A$5001,A10) -> 2 | Q10: =CustomerData[[#This Row],[avg_order_value_clean]]*CustomerData[[#This Row],[total_orders]] -> 1167.9 | R10: =IF(G10<=30,"Active",IF(G10<=90,"At Risk","Inactive")) -> At Risk | S10: =IF(M10<0.2,"Low Risk",IF(M10<0.5,"Medium Risk","High Risk")) -> Medium Risk | T10: =IF(B10<25,"Under 25",IF(B10<35,"25-34",IF(B10<45,"35-44",IF(B10<55,"45-54","55+")))) -> 55+ | U10: =TODAY()-K10 -> 2185 | V10: =IF(L10<40,"Low Loyalty",IF(L10<70,"Medium Loyalty","High Loyalty")) -> High Loyalty | W10: =IF(H10=1,"Fraudulent","Legitimate") -> Legitimate | X10: =IF(Q10<Data_Validation!$B$8,"Low Value",IF(Q10<Data_Validation!$B$9,"Medium Value","High Value")) -> Low Value | Y10: =IF(AND(X10="High Value",S10="High Risk"),"Critical - Retain",IF(AND(X10="High Value",S10<>"High Risk"),"High Value - Maintain",IF(AND(X10<>"High Value",S10="High Risk"),"At Risk - Develop","Stable"))) -> Stable | Z10: =IF(OR(B10<18,F10<0,N10<0,O10<0,O10>1,M10<0,M10>1),"Check Data","Valid") -> Check Data
A11: CUST_9322 | B11: 26 | C11: Male | D11: France | E11: 55.93 | F11: 4 | G11: 12 | H11: 0 | I11: Fashion | J11: 68.8 | K11: 45347 | L11: 63 | M11: 0.52 | N11: =IF(E11="",Data_Validation!$B$1,E11) -> 55.93 | O11: =IF(J11="",Data_Validation!$B$2,J11) -> 68.8 | P11: =COUNTIF($A$2:$A$5001,A11) -> 1 | Q11: =CustomerData[[#This Row],[avg_order_value_clean]]*CustomerData[[#This Row],[total_orders]] -> 223.72 | R11: =IF(G11<=30,"Active",IF(G11<=90,"At Risk","Inactive")) -> Active | S11: =IF(M11<0.2,"Low Risk",IF(M11<0.5,"Medium Risk","High Risk")) -> High Risk | T11: =IF(B11<25,"Under 25",IF(B11<35,"25-34",IF(B11<45,"35-44",IF(B11<55,"45-54","55+")))) -> 25-34 | U11: =TODAY()-K11 -> 914 | V11: =IF(L11<40,"Low Loyalty",IF(L11<70,"Medium Loyalty","High Loyalty")) -> Medium Loyalty | W11: =IF(H11=1,"Fraudulent","Legitimate") -> Legitimate | X11: =IF(Q11<Data_Validation!$B$8,"Low Value",IF(Q11<Data_Validation!$B$9,"Medium Value","High Value")) -> Low Value | Y11: =IF(AND(X11="High Value",S11="High Risk"),"Critical - Retain",IF(AND(X11="High Value",S11<>"High Risk"),"High Value - Maintain",IF(AND(X11<>"High Value",S11="High Risk"),"At Risk - Develop","Stable"))) -> At Risk - Develop | Z11: =IF(OR(B11<18,F11<0,N11<0,O11<0,O11>1,M11<0,M11>1),"Check Data","Valid") -> Check Data
A12: CUST_2685 | B12: 69 | C12: Female | D12: India | E12: 128.78 | F12: 7 | G12: 119 | H12: 0 | I12: Fashion | J12: 48.6 | K12: 45571 | L12: 76 | M12: 0.11 | N12: =IF(E12="",Data_Validation!$B$1,E12) -> 128.78 | O12: =IF(J12="",Data_Validation!$B$2,J12) -> 48.6 | P12: =COUNTIF($A$2:$A$5001,A12) -> 1 | Q12: =CustomerData[[#This Row],[avg_order_value_clean]]*CustomerData[[#This Row],[total_orders]] -> 901.46 | R12: =IF(G12<=30,"Active",IF(G12<=90,"At Risk","Inactive")) -> Inactive | S12: =IF(M12<0.2,"Low Risk",IF(M12<0.5,"Medium Risk","High Risk")) -> Low Risk | T12: =IF(B12<25,"Under 25",IF(B12<35,"25-34",IF(B12<45,"35-44",IF(B12<55,"45-54","55+")))) -> 55+ | U12: =TODAY()-K12 -> 690 | V12: =IF(L12<40,"Low Loyalty",IF(L12<70,"Medium Loyalty","High Loyalty")) -> High Loyalty | W12: =IF(H12=1,"Fraudulent","Legitimate") -> Legitimate | X12: =IF(Q12<Data_Validation!$B$8,"Low Value",IF(Q12<Data_Validation!$B$9,"Medium Value","High Value")) -> Low Value | Y12: =IF(AND(X12="High Value",S12="High Risk"),"Critical - Retain",IF(AND(X12="High Value",S12<>"High Risk"),"High Value - Maintain",IF(AND(X12<>"High Value",S12="High Risk"),"At Risk - Develop","Stable"))) -> Stable | Z12: =IF(OR(B12<18,F12<0,N12<0,O12<0,O12>1,M12<0,M12>1),"Check Data","Valid") -> Check Data
A13: CUST_1769 | B13: 24 | C13: Female | D13: Canada | E13: 88.23 | F13: 14 | G13: 177 | H13: 0 | I13: Beauty | J13: 83.6 | K13: 45417 | L13: 26 | M13: 0.12 | N13: =IF(E13="",Data_Validation!$B$1,E13) -> 88.23 | O13: =IF(J13="",Data_Validation!$B$2,J13) -> 83.6 | P13: =COUNTIF($A$2:$A$5001,A13) -> 3 | Q13: =CustomerData[[#This Row],[avg_order_value_clean]]*CustomerData[[#This Row],[total_orders]] -> 1235.22 | R13: =IF(G13<=30,"Active",IF(G13<=90,"At Risk","Inactive")) -> Inactive | S13: =IF(M13<0.2,"Low Risk",IF(M13<0.5,"Medium Risk","High Risk")) -> Low Risk | T13: =IF(B13<25,"Under 25",IF(B13<35,"25-34",IF(B13<45,"35-44",IF(B13<55,"45-54","55+")))) -> Under 25 | U13: =TODAY()-K13 -> 844 | V13: =IF(L13<40,"Low Loyalty",IF(L13<70,"Medium Loyalty","High Loyalty")) -> Low Loyalty | W13: =IF(H13=1,"Fraudulent","Legitimate") -> Legitimate | X13: =IF(Q13<Data_Validation!$B$8,"Low Value",IF(Q13<Data_Validation!$B$9,"Medium Value","High Value")) -> Low Value | Y13: =IF(AND(X13="High Value",S13="High Risk"),"Critical - Retain",IF(AND(X13="High Value",S13<>"High Risk"),"High Value - Maintain",IF(AND(X13<>"High Value",S13="High Risk"),"At Risk - Develop","Stable"))) -> Stable | Z13: =IF(OR(B13<18,F13<0,N13<0,O13<0,O13>1,M13<0,M13>1),"Check Data","Valid") -> Check Data
A14: CUST_7949 | B14: 19 | C14: Male | D14: India | E14: 77.24 | F14: 12 | G14: 128 | H14: 0 | I14: Home | J14: 26.5 | K14: 44375 | L14: 45 | M14: 0.63 | N14: =IF(E14="",Data_Validation!$B$1,E14) -> 77.24 | O14: =IF(J14="",Data_Validation!$B$2,J14) -> 26.5 | P14: =COUNTIF($A$2:$A$5001,A14) -> 3 | Q14: =CustomerData[[#This Row],[avg_order_value_clean]]*CustomerData[[#This Row],[total_orders]] -> 926.88 | R14: =IF(G14<=30,"Active",IF(G14<=90,"At Risk","Inactive")) -> Inactive | S14: =IF(M14<0.2,"Low Risk",IF(M14<0.5,"Medium Risk","High Risk")) -> High Risk | T14: =IF(B14<25,"Under 25",IF(B14<35,"25-34",IF(B14<45,"35-44",IF(B14<55,"45-54","55+")))) -> Under 25 | U14: =TODAY()-K14 -> 1886 | V14: =IF(L14<40,"Low Loyalty",IF(L14<70,"Medium Loyalty","High Loyalty")) -> Medium Loyalty | W14: =IF(H14=1,"Fraudulent","Legitimate") -> Legitimate | X14: =IF(Q14<Data_Validation!$B$8,"Low Value",IF(Q14<Data_Validation!$B$9,"Medium Value","High Value")) -> Low Value | Y14: =IF(AND(X14="High Value",S14="High Risk"),"Critical - Retain",IF(AND(X14="High Value",S14<>"High Risk"),"High Value - Maintain",IF(AND(X14<>"High Value",S14="High Risk"),"At Risk - Develop","Stable"))) -> At Risk - Develop | Z14: =IF(OR(B14<18,F14<0,N14<0,O14<0,O14>1,M14<0,M14>1),"Check Data","Valid") -> Check Data
A15: CUST_3433 | B15: 71 | C15: Female | D15: Brazil | E15: 91.39 | F15: 8 | G15: 50 | H15: 0 | I15: Home | J15: 21.1 | K15: 44757 | L15: 95 | M15: 0.34 | N15: =IF(E15="",Data_Validation!$B$1,E15) -> 91.39 | O15: =IF(J15="",Data_Validation!$B$2,J15) -> 21.1 | P15: =COUNTIF($A$2:$A$5001,A15) -> 2 | Q15: =CustomerData[[#This Row],[avg_order_value_clean]]*CustomerData[[#This Row],[total_orders]] -> 731.12 | R15: =IF(G15<=30,"Active",IF(G15<=90,"At Risk","Inactive")) -> At Risk | S15: =IF(M15<0.2,"Low Risk",IF(M15<0.5,"Medium Risk","High Risk")) -> Medium Risk | T15: =IF(B15<25,"Under 25",IF(B15<35,"25-34",IF(B15<45,"35-44",IF(B15<55,"45-54","55+")))) -> 55+ | U15: =TODAY()-K15 -> 1504 | V15: =IF(L15<40,"Low Loyalty",IF(L15<70,"Medium Loyalty","High Loyalty")) -> High Loyalty | W15: =IF(H15=1,"Fraudulent","Legitimate") -> Legitimate | X15: =IF(Q15<Data_Validation!$B$8,"Low Value",IF(Q15<Data_Validation!$B$9,"Medium Value","High Value")) -> Low Value | Y15: =IF(AND(X15="High Value",S15="High Risk"),"Critical - Retain",IF(AND(X15="High Value",S15<>"High Risk"),"High Value - Maintain",IF(AND(X15<>"High Value",S15="High Risk"),"At Risk - Develop","Stable"))) -> Stable | Z15: =IF(OR(B15<18,F15<0,N15<0,O15<0,O15>1,M15<0,M15>1),"Check Data","Valid") -> Check Data
A16: CUST_6311 | B16: 73 | C16: Female | D16: India | E16: 131.23 | F16: 7 | G16: 41 | H16: 0 | I16: Sports | J16: 80.3 | K16: 45433 | L16: 35 | M16: 0.61 | N16: =IF(E16="",Data_Validation!$B$1,E16) -> 131.23 | O16: =IF(J16="",Data_Validation!$B$2,J16) -> 80.3 | P16: =COUNTIF($A$2:$A$5001,A16) -> 1 | Q16: =CustomerData[[#This Row],[avg_order_value_clean]]*CustomerData[[#This Row],[total_orders]] -> 918.61 | R16: =IF(G16<=30,"Active",IF(G16<=90,"At Risk","Inactive")) -> At Risk | S16: =IF(M16<0.2,"Low Risk",IF(M16<0.5,"Medium Risk","High Risk")) -> High Risk | T16: =IF(B16<25,"Under 25",IF(B16<35,"25-34",IF(B16<45,"35-44",IF(B16<55,"45-54","55+")))) -> 55+ | U16: =TODAY()-K16 -> 828 | V16: =IF(L16<40,"Low Loyalty",IF(L16<70,"Medium Loyalty","High Loyalty")) -> Low Loyalty | W16: =IF(H16=1,"Fraudulent","Legitimate") -> Legitimate | X16: =IF(Q16<Data_Validation!$B$8,"Low Value",IF(Q16<Data_Validation!$B$9,"Medium Value","High Value")) -> Low Value | Y16: =IF(AND(X16="High Value",S16="High Risk"),"Critical - Retain",IF(AND(X16="High Value",S16<>"High Risk"),"High Value - Maintain",IF(AND(X16<>"High Value",S16="High Risk"),"At Risk - Develop","Stable"))) -> At Risk - Develop | Z16: =IF(OR(B16<18,F16<0,N16<0,O16<0,O16>1,M16<0,M16>1),"Check Data","Valid") -> Check Data
... A31: CUST_5658 | B31: 42 | C31: Male | D31: Brazil | E31: 61.94 | F31: 8 | G31: 17 | H31: 0 | I31: Beauty | J31: 99 | K31: 44457 | L31: 49 | M31: 0.41 | N31: =IF(E31="",Data_Validation!$B$1,E31) -> 61.94 | O31: =IF(J31="",Data_Validation!$B$2,J31) -> 99 | P31: =COUNTIF($A$2:$A$5001,A31) -> 3 | Q31: =CustomerData[[#This Row],[avg_order_value_clean]]*CustomerData[[#This Row],[total_orders]] -> 495.52 | R31: =IF(G31<=30,"Active",IF(G31<=90,"At Risk","Inactive")) -> Active | S31: =IF(M31<0.2,"Low Risk",IF(M31<0.5,"Medium Risk","High Risk")) -> Medium Risk | T31: =IF(B31<25,"Under 25",IF(B31<35,"25-34",IF(B31<45,"35-44",IF(B31<55,"45-54","55+")))) -> 35-44 | U31: =TODAY()-K31 -> 1804 | V31: =IF(L31<40,"Low Loyalty",IF(L31<70,"Medium Loyalty","High Loyalty")) -> Medium Loyalty | W31: =IF(H31=1,"Fraudulent","Legitimate") -> Legitimate | X31: =IF(Q31<Data_Validation!$B$8,"Low Value",IF(Q31<Data_Validation!$B$9,"Medium Value","High Value")) -> Low Value | Y31: =IF(AND(X31="High Value",S31="High Risk"),"Critical - Retain",IF(AND(X31="High Value",S31<>"High Risk"),"High Value - Maintain",IF(AND(X31<>"High Value",S31="High Risk"),"At Risk - Develop","Stable"))) -> Stable | Z31: =IF(OR(B31<18,F31<0,N31<0,O31<0,O31>1,M31<0,M31>1),"Check Data","Valid") -> Check Data
A32: CUST_2899 | B32: 48 | C32: Female | D32: Canada | F32: 8 | G32: 200 | H32: 0 | I32: Home | J32: 43.3 | K32: 44924 | L32: 3 | M32: 0.27 | N32: =IF(E32="",Data_Validation!$B$1,E32) -> 250 | O32: =IF(J32="",Data_Validation!$B$2,J32) -> 43.3 | P32: =COUNTIF($A$2:$A$5001,A32) -> 1 | Q32: =CustomerData[[#This Row],[avg_order_value_clean]]*CustomerData[[#This Row],[total_orders]] -> 2000 | R32: =IF(G32<=30,"Active",IF(G32<=90,"At Risk","Inactive")) -> Inactive | S32: =IF(M32<0.2,"Low Risk",IF(M32<0.5,"Medium Risk","High Risk")) -> Medium Risk | T32: =IF(B32<25,"Under 25",IF(B32<35,"25-34",IF(B32<45,"35-44",IF(B32<55,"45-54","55+")))) -> 45-54 | U32: =TODAY()-K32 -> 1337 | V32: =IF(L32<40,"Low Loyalty",IF(L32<70,"Medium Loyalty","High Loyalty")) -> Low Loyalty | W32: =IF(H32=1,"Fraudulent","Legitimate") -> Legitimate | X32: =IF(Q32<Data_Validation!$B$8,"Low Value",IF(Q32<Data_Validation!$B$9,"Medium Value","High Value")) -> High Value | Y32: =IF(AND(X32="High Value",S32="High Risk"),"Critical - Retain",IF(AND(X32="High Value",S32<>"High Risk"),"High Value - Maintain",IF(AND(X32<>"High Value",S32="High Risk"),"At Risk - Develop","Stable"))) -> High Value - Maintain | Z32: =IF(OR(B32<18,F32<0,N32<0,O32<0,O32>1,M32<0,M32>1),"Check Data","Valid") -> Check Data
A33: CUST_8734 | B33: 67 | C33: Male | D33: Australia | E33: 109.18 | F33: 11 | G33: 252 | H33: 0 | I33: Sports | J33: 58.6 | K33: 44429 | L33: 17 | M33: 0.31 | N33: =IF(E33="",Data_Validation!$B$1,E33) -> 109.18 | O33: =IF(J33="",Data_Validation!$B$2,J33) -> 58.6 | P33: =COUNTIF($A$2:$A$5001,A33) -> 1 | Q33: =CustomerData[[#This Row],[avg_order_value_clean]]*CustomerData[[#This Row],[total_orders]] -> 1200.98 | R33: =IF(G33<=30,"Active",IF(G33<=90,"At Risk","Inactive")) -> Inactive | S33: =IF(M33<0.2,"Low Risk",IF(M33<0.5,"Medium Risk","High Risk")) -> Medium Risk | T33: =IF(B33<25,"Under 25",IF(B33<35,"25-34",IF(B33<45,"35-44",IF(B33<55,"45-54","55+")))) -> 55+ | U33: =TODAY()-K33 -> 1832 | V33: =IF(L33<40,"Low Loyalty",IF(L33<70,"Medium Loyalty","High Loyalty")) -> Low Loyalty | W33: =IF(H33=1,"Fraudulent","Legitimate") -> Legitimate | X33: =IF(Q33<Data_Validation!$B$8,"Low Value",IF(Q33<Data_Validation!$B$9,"Medium Value","High Value")) -> Low Value | Y33: =IF(AND(X33="High Value",S33="High Risk"),"Critical - Retain",IF(AND(X33="High Value",S33<>"High Risk"),"High Value - Maintain",IF(AND(X33<>"High Value",S33="High Risk"),"At Risk - Develop","Stable"))) -> Stable | Z33: =IF(OR(B33<18,F33<0,N33<0,O33<0,O33>1,M33<0,M33>1),"Check Data","Valid") -> Check Data
A34: CUST_2267 | B34: 37 | C34: Male | D34: Australia | E34: 75.98 | F34: 6 | G34: 191 | H34: 0 | I34: Beauty | J34: 59.4 | K34: 44202 | L34: 25 | M34: 0.22 | N34: =IF(E34="",Data_Validation!$B$1,E34) -> 75.98 | O34: =IF(J34="",Data_Validation!$B$2,J34) -> 59.4 | P34: =COUNTIF($A$2:$A$5001,A34) -> 1 | Q34: =CustomerData[[#This Row],[avg_order_value_clean]]*CustomerData[[#This Row],[total_orders]] -> 455.88 | R34: =IF(G34<=30,"Active",IF(G34<=90,"At Risk","Inactive")) -> Inactive | S34: =IF(M34<0.2,"Low Risk",IF(M34<0.5,"Medium Risk","High Risk")) -> Medium Risk | T34: =IF(B34<25,"Under 25",IF(B34<35,"25-34",IF(B34<45,"35-44",IF(B34<55,"45-54","55+")))) -> 35-44 | U34: =TODAY()-K34 -> 2059 | V34: =IF(L34<40,"Low Loyalty",IF(L34<70,"Medium Loyalty","High Loyalty")) -> Low Loyalty | W34: =IF(H34=1,"Fraudulent","Legitimate") -> Legitimate | X34: =IF(Q34<Data_Validation!$B$8,"Low Value",IF(Q34<Data_Validation!$B$9,"Medium Value","High Value")) -> Low Value | Y34: =IF(AND(X34="High Value",S34="High Risk"),"Critical - Retain",IF(AND(X34="High Value",S34<>"High Risk"),"High Value - Maintain",IF(AND(X34<>"High Value",S34="High Risk"),"At Risk - Develop","Stable"))) -> Stable | Z34: =IF(OR(B34<18,F34<0,N34<0,O34<0,O34>1,M34<0,M34>1),"Check Data","Valid") -> Check Data
A35: CUST_2528 | B35: 61 | C35: Female | D35: France | E35: 46.66 | F35: 7 | G35: 48 | H35: 0 | I35: Home | J35: 34.6 | K35: 45282 | L35: 94 | M35: 0.34 | N35: =IF(E35="",Data_Validation!$B$1,E35) -> 46.66 | O35: =IF(J35="",Data_Validation!$B$2,J35) -> 34.6 | P35: =COUNTIF($A$2:$A$5001,A35) -> 1 | Q35: =CustomerData[[#This Row],[avg_order_value_clean]]*CustomerData[[#This Row],[total_orders]] -> 326.62 | R35: =IF(G35<=30,"Active",IF(G35<=90,"At Risk","Inactive")) -> At Risk | S35: =IF(M35<0.2,"Low Risk",IF(M35<0.5,"Medium Risk","High Risk")) -> Medium Risk | T35: =IF(B35<25,"Under 25",IF(B35<35,"25-34",IF(B35<45,"35-44",IF(B35<55,"45-54","55+")))) -> 55+ | U35: =TODAY()-K35 -> 979 | V35: =IF(L35<40,"Low Loyalty",IF(L35<70,"Medium Loyalty","High Loyalty")) -> High Loyalty | W35: =IF(H35=1,"Fraudulent","Legitimate") -> Legitimate | X35: =IF(Q35<Data_Validation!$B$8,"Low Value",IF(Q35<Data_Validation!$B$9,"Medium Value","High Value")) -> Low Value | Y35: =IF(AND(X35="High Value",S35="High Risk"),"Critical - Retain",IF(AND(X35="High Value",S35<>"High Risk"),"High Value - Maintain",IF(AND(X35<>"High Value",S35="High Risk"),"At Risk - Develop","Stable"))) -> Stable | Z35: =IF(OR(B35<18,F35<0,N35<0,O35<0,O35>1,M35<0,M35>1),"Check Data","Valid") -> Check Data
A36: CUST_4556 | B36: 72 | C36: Female | D36: China | E36: 106.23 | F36: 13 | G36: 93 | H36: 0 | I36: Sports | J36: 54.5 | K36: 45209 | L36: 14 | M36: 0.25 | N36: =IF(E36="",Data_Validation!$B$1,E36) -> 106.23 | O36: =IF(J36="",Data_Validation!$B$2,J36) -> 54.5 | P36: =COUNTIF($A$2:$A$5001,A36) -> 1 | Q36: =CustomerData[[#This Row],[avg_order_value_clean]]*CustomerData[[#This Row],[total_orders]] -> 1380.99 | R36: =IF(G36<=30,"Active",IF(G36<=90,"At Risk","Inactive")) -> Inactive | S36: =IF(M36<0.2,"Low Risk",IF(M36<0.5,"Medium Risk","High Risk")) -> Medium Risk | T36: =IF(B36<25,"Under 25",IF(B36<35,"25-34",IF(B36<45,"35-44",IF(B36<55,"45-54","55+")))) -> 55+ | U36: =TODAY()-K36 -> 1052 | V36: =IF(L36<40,"Low Loyalty",IF(L36<70,"Medium Loyalty","High Loyalty")) -> Low Loyalty | W36: =IF(H36=1,"Fraudulent","Legitimate") -> Legitimate | X36: =IF(Q36<Data_Validation!$B$8,"Low Value",IF(Q36<Data_Validation!$B$9,"Medium Value","High Value")) -> Low Value | Y36: =IF(AND(X36="High Value",S36="High Risk"),"Critical - Retain",IF(AND(X36="High Value",S36<>"High Risk"),"High Value - Maintain",IF(AND(X36<>"High Value",S36="High Risk"),"At Risk - Develop","Stable"))) -> Stable | Z36: =IF(OR(B36<18,F36<0,N36<0,O36<0,O36>1,M36<0,M36>1),"Check Data","Valid") -> Check Data
A37: CUST_4890 | B37: 34 | C37: Male | D37: Germany | E37: 112.56 | F37: 13 | G37: 236 | H37: 0 | I37: Beauty | J37: 58.3 | K37: 44471 | L37: 93 | M37: 0.28 | N37: =IF(E37="",Data_Validation!$B$1,E37) -> 112.56 | O37: =IF(J37="",Data_Validation!$B$2,J37) -> 58.3 | P37: =COUNTIF($A$2:$A$5001,A37) -> 1 | Q37: =CustomerData[[#This Row],[avg_order_value_clean]]*CustomerData[[#This Row],[total_orders]] -> 1463.28 | R37: =IF(G37<=30,"Active",IF(G37<=90,"At Risk","Inactive")) -> Inactive | S37: =IF(M37<0.2,"Low Risk",IF(M37<0.5,"Medium Risk","High Risk")) -> Medium Risk | T37: =IF(B37<25,"Under 25",IF(B37<35,"25-34",IF(B37<45,"35-44",IF(B37<55,"45-54","55+")))) -> 25-34 | U37: =TODAY()-K37 -> 1790 | V37: =IF(L37<40,"Low Loyalty",IF(L37<70,"Medium Loyalty","High Loyalty")) -> High Loyalty | W37: =IF(H37=1,"Fraudulent","Legitimate") -> Legitimate | X37: =IF(Q37<Data_Validation!$B$8,"Low Value",IF(Q37<Data_Validation!$B$9,"Medium Value","High Value")) -> Low Value | Y37: =IF(AND(X37="High Value",S37="High Risk"),"Critical - Retain",IF(AND(X37="High Value",S37<>"High Risk"),"High Value - Maintain",IF(AND(X37<>"High Value",S37="High Risk"),"At Risk - Develop","Stable"))) -> Stable | Z37: =IF(OR(B37<18,F37<0,N37<0,O37<0,O37>1,M37<0,M37>1),"Check Data","Valid") -> Check Data
A38: CUST_9838 | B38: 62 | C38: Other | D38: China | E38: 175.73 | F38: 14 | G38: 221 | H38: 0 | I38: Fashion | J38: 76.1 | K38: 44501 | L38: 5 | M38: 0.33 | N38: =IF(E38="",Data_Validation!$B$1,E38) -> 175.73 | O38: =IF(J38="",Data_Validation!$B$2,J38) -> 76.1 | P38: =COUNTIF($A$2:$A$5001,A38) -> 1 | Q38: =CustomerData[[#This Row],[avg_order_value_clean]]*CustomerData[[#This Row],[total_orders]] -> 2460.22 | R38: =IF(G38<=30,"Active",IF(G38<=90,"At Risk","Inactive")) -> Inactive | S38: =IF(M38<0.2,"Low Risk",IF(M38<0.5,"Medium Risk","High Risk")) -> Medium Risk | T38: =IF(B38<25,"Under 25",IF(B38<35,"25-34",IF(B38<45,"35-44",IF(B38<55,"45-54","55+")))) -> 55+ | U38: =TODAY()-K38 -> 1760 | V38: =IF(L38<40,"Low Loyalty",IF(L38<70,"Medium Loyalty","High Loyalty")) -> Low Loyalty | W38: =IF(H38=1,"Fraudulent","Legitimate") -> Legitimate | X38: =IF(Q38<Data_Validation!$B$8,"Low Value",IF(Q38<Data_Validation!$B$9,"Medium Value","High Value")) -> High Value | Y38: =IF(AND(X38="High Value",S38="High Risk"),"Critical - Retain",IF(AND(X38="High Value",S38<>"High Risk"),"High Value - Maintain",IF(AND(X38<>"High Value",S38="High Risk"),"At Risk - Develop","Stable"))) -> High Value - Maintain | Z38: =IF(OR(B38<18,F38<0,N38<0,O38<0,O38>1,M38<0,M38>1),"Check Data","Valid") -> Check Data
A39: CUST_6393 | B39: 19 | C39: Female | D39: Canada | E39: 22.72 | F39: 12 | G39: 166 | H39: 0 | I39: Sports | J39: 66.2 | K39: 45462 | L39: 71 | M39: 0.05 | N39: =IF(E39="",Data_Validation!$B$1,E39) -> 22.72 | O39: =IF(J39="",Data_Validation!$B$2,J39) -> 66.2 | P39: =COUNTIF($A$2:$A$5001,A39) -> 1 | Q39: =CustomerData[[#This Row],[avg_order_value_clean]]*CustomerData[[#This Row],[total_orders]] -> 272.64 | R39: =IF(G39<=30,"Active",IF(G39<=90,"At Risk","Inactive")) -> Inactive | S39: =IF(M39<0.2,"Low Risk",IF(M39<0.5,"Medium Risk","High Risk")) -> Low Risk | T39: =IF(B39<25,"Under 25",IF(B39<35,"25-34",IF(B39<45,"35-44",IF(B39<55,"45-54","55+")))) -> Under 25 | U39: =TODAY()-K39 -> 799 | V39: =IF(L39<40,"Low Loyalty",IF(L39<70,"Medium Loyalty","High Loyalty")) -> High Loyalty | W39: =IF(H39=1,"Fraudulent","Legitimate") -> Legitimate | X39: =IF(Q39<Data_Validation!$B$8,"Low Value",IF(Q39<Data_Validation!$B$9,"Medium Value","High Value")) -> Low Value | Y39: =IF(AND(X39="High Value",S39="High Risk"),"Critical - Retain",IF(AND(X39="High Value",S39<>"High Risk"),"High Value - Maintain",IF(AND(X39<>"High Value",S39="High Risk"),"At Risk - Develop","Stable"))) -> Stable | Z39: =IF(OR(B39<18,F39<0,N39<0,O39<0,O39>1,M39<0,M39>1),"Check Data","Valid") -> Check Data
A40: CUST_9792 | B40: 42 | C40: Male | D40: Canada | E40: 103.97 | F40: 13 | G40: 253 | H40: 0 | I40: Beauty | J40: 44.7 | K40: 45611 | L40: 83 | M40: 0.09 | N40: =IF(E40="",Data_Validation!$B$1,E40) -> 103.97 | O40: =IF(J40="",Data_Validation!$B$2,J40) -> 44.7 | P40: =COUNTIF($A$2:$A$5001,A40) -> 3 | Q40: =CustomerData[[#This Row],[avg_order_value_clean]]*CustomerData[[#This Row],[total_orders]] -> 1351.61 | R40: =IF(G40<=30,"Active",IF(G40<=90,"At Risk","Inactive")) -> Inactive | S40: =IF(M40<0.2,"Low Risk",IF(M40<0.5,"Medium Risk","High Risk")) -> Low Risk | T40: =IF(B40<25,"Under 25",IF(B40<35,"25-34",IF(B40<45,"35-44",IF(B40<55,"45-54","55+")))) -> 35-44 | U40: =TODAY()-K40 -> 650 | V40: =IF(L40<40,"Low Loyalty",IF(L40<70,"Medium Loyalty","High Loyalty")) -> High Loyalty | W40: =IF(H40=1,"Fraudulent","Legitimate") -> Legitimate | X40: =IF(Q40<Data_Validation!$B$8,"Low Value",IF(Q40<Data_Validation!$B$9,"Medium Value","High Value")) -> Low Value | Y40: =IF(AND(X40="High Value",S40="High Risk"),"Critical - Retain",IF(AND(X40="High Value",S40<>"High Risk"),"High Value - Maintain",IF(AND(X40<>"High Value",S40="High Risk"),"At Risk - Develop","Stable"))) -> Stable | Z40: =IF(OR(B40<18,F40<0,N40<0,O40<0,O40>1,M40<0,M40>1),"Check Data","Valid") -> Check Data
A41: CUST_9433 | B41: 30 | C41: Female | D41: USA | E41: 43.35 | F41: 13 | G41: 56 | H41: 0 | I41: Electronics | J41: 19.1 | K41: 45682 | L41: 33 | M41: 0.08 | N41: =IF(E41="",Data_Validation!$B$1,E41) -> 43.35 | O41: =IF(J41="",Data_Validation!$B$2,J41) -> 19.1 | P41: =COUNTIF($A$2:$A$5001,A41) -> 3 | Q41: =CustomerData[[#This Row],[avg_order_value_clean]]*CustomerData[[#This Row],[total_orders]] -> 563.55 | R41: =IF(G41<=30,"Active",IF(G41<=90,"At Risk","Inactive")) -> At Risk | S41: =IF(M41<0.2,"Low Risk",IF(M41<0.5,"Medium Risk","High Risk")) -> Low Risk | T41: =IF(B41<25,"Under 25",IF(B41<35,"25-34",IF(B41<45,"35-44",IF(B41<55,"45-54","55+")))) -> 25-34 | U41: =TODAY()-K41 -> 579 | V41: =IF(L41<40,"Low Loyalty",IF(L41<70,"Medium Loyalty","High Loyalty")) -> Low Loyalty | W41: =IF(H41=1,"Fraudulent","Legitimate") -> Legitimate | X41: =IF(Q41<Data_Validation!$B$8,"Low Value",IF(Q41<Data_Validation!$B$9,"Medium Value","High Value")) -> Low Value | Y41: =IF(AND(X41="High Value",S41="High Risk"),"Critical - Retain",IF(AND(X41="High Value",S41<>"High Risk"),"High Value - Maintain",IF(AND(X41<>"High Value",S41="High Risk"),"At Risk - Develop","Stable"))) -> Stable | Z41: =IF(OR(B41<18,F41<0,N41<0,O41<0,O41>1,M41<0,M41>1),"Check Data","Valid") -> Check Data
A42: CUST_8513 | B42: 75 | C42: Female | D42: Australia | E42: 48.94 | F42: 11 | G42: 5 | H42: 0 | I42: Fashion | J42: 2.5 | K42: 44609 | L42: 85 | M42: 0.14 | N42: =IF(E42="",Data_Validation!$B$1,E42) -> 48.94 | O42: =IF(J42="",Data_Validation!$B$2,J42) -> 2.5 | P42: =COUNTIF($A$2:$A$5001,A42) -> 1 | Q42: =CustomerData[[#This Row],[avg_order_value_clean]]*CustomerData[[#This Row],[total_orders]] -> 538.34 | R42: =IF(G42<=30,"Active",IF(G42<=90,"At Risk","Inactive")) -> Active | S42: =IF(M42<0.2,"Low Risk",IF(M42<0.5,"Medium Risk","High Risk")) -> Low Risk | T42: =IF(B42<25,"Under 25",IF(B42<35,"25-34",IF(B42<45,"35-44",IF(B42<55,"45-54","55+")))) -> 55+ | U42: =TODAY()-K42 -> 1652 | V42: =IF(L42<40,"Low Loyalty",IF(L42<70,"Medium Loyalty","High Loyalty")) -> High Loyalty | W42: =IF(H42=1,"Fraudulent","Legitimate") -> Legitimate | X42: =IF(Q42<Data_Validation!$B$8,"Low Value",IF(Q42<Data_Validation!$B$9,"Medium Value","High Value")) -> Low Value | Y42: =IF(AND(X42="High Value",S42="High Risk"),"Critical - Retain",IF(AND(X42="High Value",S42<>"High Risk"),"High Value - Maintain",IF(AND(X42<>"High Value",S42="High Risk"),"At Risk - Develop","Stable"))) -> Stable | Z42: =IF(OR(B42<18,F42<0,N42<0,O42<0,O42>1,M42<0,M42>1),"Check Data","Valid") -> Check Data
A43: CUST_3612 | B43: 56 | C43: Female | D43: UK | E43: 53.17 | F43: 5 | G43: 237 | H43: 0 | I43: Sports | J43: 65.2 | K43: 45023 | L43: 51 | M43: 0.09 | N43: =IF(E43="",Data_Validation!$B$1,E43) -> 53.17 | O43: =IF(J43="",Data_Validation!$B$2,J43) -> 65.2 | P43: =COUNTIF($A$2:$A$5001,A43) -> 1 | Q43: =CustomerData[[#This Row],[avg_order_value_clean]]*CustomerData[[#This Row],[total_orders]] -> 265.85 | R43: =IF(G43<=30,"Active",IF(G43<=90,"At Risk","Inactive")) -> Inactive | S43: =IF(M43<0.2,"Low Risk",IF(M43<0.5,"Medium Risk","High Risk")) -> Low Risk | T43: =IF(B43<25,"Under 25",IF(B43<35,"25-34",IF(B43<45,"35-44",IF(B43<55,"45-54","55+")))) -> 55+ | U43: =TODAY()-K43 -> 1238 | V43: =IF(L43<40,"Low Loyalty",IF(L43<70,"Medium Loyalty","High Loyalty")) -> Medium Loyalty | W43: =IF(H43=1,"Fraudulent","Legitimate") -> Legitimate | X43: =IF(Q43<Data_Validation!$B$8,"Low Value",IF(Q43<Data_Validation!$B$9,"Medium Value","High Value")) -> Low Value | Y43: =IF(AND(X43="High Value",S43="High Risk"),"Critical - Retain",IF(AND(X43="High Value",S43<>"High Risk"),"High Value - Maintain",IF(AND(X43<>"High Value",S43="High Risk"),"At Risk - Develop","Stable"))) -> Stable | Z43: =IF(OR(B43<18,F43<0,N43<0,O43<0,O43>1,M43<0,M43>1),"Check Data","Valid") -> Check Data
A44: CUST_8041 | B44: 45 | C44: Female | D44: Japan | E44: 26.94 | F44: 10 | G44: 220 | H44: 0 | I44: Home | J44: 47.8 | K44: 45673 | L44: 85 | M44: 0.38 | N44: =IF(E44="",Data_Validation!$B$1,E44) -> 26.94 | O44: =IF(J44="",Data_Validation!$B$2,J44) -> 47.8 | P44: =COUNTIF($A$2:$A$5001,A44) -> 2 | Q44: =CustomerData[[#This Row],[avg_order_value_clean]]*CustomerData[[#This Row],[total_orders]] -> 269.4 | R44: =IF(G44<=30,"Active",IF(G44<=90,"At Risk","Inactive")) -> Inactive | S44: =IF(M44<0.2,"Low Risk",IF(M44<0.5,"Medium Risk","High Risk")) -> Medium Risk | T44: =IF(B44<25,"Under 25",IF(B44<35,"25-34",IF(B44<45,"35-44",IF(B44<55,"45-54","55+")))) -> 45-54 | U44: =TODAY()-K44 -> 588 | V44: =IF(L44<40,"Low Loyalty",IF(L44<70,"Medium Loyalty","High Loyalty")) -> High Loyalty | W44: =IF(H44=1,"Fraudulent","Legitimate") -> Legitimate | X44: =IF(Q44<Data_Validation!$B$8,"Low Value",IF(Q44<Data_Validation!$B$9,"Medium Value","High Value")) -> Low Value | Y44: =IF(AND(X44="High Value",S44="High Risk"),"Critical - Retain",IF(AND(X44="High Value",S44<>"High Risk"),"High Value - Maintain",IF(AND(X44<>"High Value",S44="High Risk"),"At Risk - Develop","Stable"))) -> Stable | Z44: =IF(OR(B44<18,F44<0,N44<0,O44<0,O44>1,M44<0,M44>1),"Check Data","Valid") -> Check Data
... A54: CUST_4073 | B54: 37 | C54: Male | D54: Canada | E54: 99.86 | F54: 13 | G54: 209 | H54: 0 | I54: Fashion | J54: 96.7 | K54: 45832 | L54: 34 | M54: 0.24 | N54: =IF(E54="",Data_Validation!$B$1,E54) -> 99.86 | O54: =IF(J54="",Data_Validation!$B$2,J54) -> 96.7 | P54: =COUNTIF($A$2:$A$5001,A54) -> 1 | Q54: =CustomerData[[#This Row],[avg_order_value_clean]]*CustomerData[[#This Row],[total_orders]] -> 1298.18 | R54: =IF(G54<=30,"Active",IF(G54<=90,"At Risk","Inactive")) -> Inactive | S54: =IF(M54<0.2,"Low Risk",IF(M54<0.5,"Medium Risk","High Risk")) -> Medium Risk | T54: =IF(B54<25,"Under 25",IF(B54<35,"25-34",IF(B54<45,"35-44",IF(B54<55,"45-54","55+")))) -> 35-44 | U54: =TODAY()-K54 -> 429 | V54: =IF(L54<40,"Low Loyalty",IF(L54<70,"Medium Loyalty","High Loyalty")) -> Low Loyalty | W54: =IF(H54=1,"Fraudulent","Legitimate") -> Legitimate | X54: =IF(Q54<Data_Validation!$B$8,"Low Value",IF(Q54<Data_Validation!$B$9,"Medium Value","High Value")) -> Low Value | Y54: =IF(AND(X54="High Value",S54="High Risk"),"Critical - Retain",IF(AND(X54="High Value",S54<>"High Risk"),"High Value - Maintain",IF(AND(X54<>"High Value",S54="High Risk"),"At Risk - Develop","Stable"))) -> Stable | Z54: =IF(OR(B54<18,F54<0,N54<0,O54<0,O54>1,M54<0,M54>1),"Check Data","Valid") -> Check Data
A55: CUST_2021 | B55: 22 | C55: Female | D55: USA | F55: 9 | G55: 255 | H55: 0 | I55: Home | J55: 36.5 | K55: 44545 | L55: 65 | M55: 0.13 | N55: =IF(E55="",Data_Validation!$B$1,E55) -> 250 | O55: =IF(J55="",Data_Validation!$B$2,J55) -> 36.5 | P55: =COUNTIF($A$2:$A$5001,A55) -> 1 | Q55: =CustomerData[[#This Row],[avg_order_value_clean]]*CustomerData[[#This Row],[total_orders]] -> 2250 | R55: =IF(G55<=30,"Active",IF(G55<=90,"At Risk","Inactive")) -> Inactive | S55: =IF(M55<0.2,"Low Risk",IF(M55<0.5,"Medium Risk","High Risk")) -> Low Risk | T55: =IF(B55<25,"Under 25",IF(B55<35,"25-34",IF(B55<45,"35-44",IF(B55<55,"45-54","55+")))) -> Under 25 | U55: =TODAY()-K55 -> 1716 | V55: =IF(L55<40,"Low Loyalty",IF(L55<70,"Medium Loyalty","High Loyalty")) -> Medium Loyalty | W55: =IF(H55=1,"Fraudulent","Legitimate") -> Legitimate | X55: =IF(Q55<Data_Validation!$B$8,"Low Value",IF(Q55<Data_Validation!$B$9,"Medium Value","High Value")) -> High Value | Y55: =IF(AND(X55="High Value",S55="High Risk"),"Critical - Retain",IF(AND(X55="High Value",S55<>"High Risk"),"High Value - Maintain",IF(AND(X55<>"High Value",S55="High Risk"),"At Risk - Develop","Stable"))) -> High Value - Maintain | Z55: =IF(OR(B55<18,F55<0,N55<0,O55<0,O55>1,M55<0,M55>1),"Check Data","Valid") -> Check Data
A56: CUST_4843 | B56: 36 | C56: Male | D56: Canada | E56: 50.6 | F56: 11 | G56: 311 | H56: 0 | I56: Beauty | J56: 79.2 | K56: 44830 | L56: 32 | M56: 0.36 | N56: =IF(E56="",Data_Validation!$B$1,E56) -> 50.6 | O56: =IF(J56="",Data_Validation!$B$2,J56) -> 79.2 | P56: =COUNTIF($A$2:$A$5001,A56) -> 1 | Q56: =CustomerData[[#This Row],[avg_order_value_clean]]*CustomerData[[#This Row],[total_orders]] -> 556.6 | R56: =IF(G56<=30,"Active",IF(G56<=90,"At Risk","Inactive")) -> Inactive | S56: =IF(M56<0.2,"Low Risk",IF(M56<0.5,"Medium Risk","High Risk")) -> Medium Risk | T56: =IF(B56<25,"Under 25",IF(B56<35,"25-34",IF(B56<45,"35-44",IF(B56<55,"45-54","55+")))) -> 35-44 | U56: =TODAY()-K56 -> 1431 | V56: =IF(L56<40,"Low Loyalty",IF(L56<70,"Medium Loyalty","High Loyalty")) -> Low Loyalty | W56: =IF(H56=1,"Fraudulent","Legitimate") -> Legitimate | X56: =IF(Q56<Data_Validation!$B$8,"Low Value",IF(Q56<Data_Validation!$B$9,"Medium Value","High Value")) -> Low Value | Y56: =IF(AND(X56="High Value",S56="High Risk"),"Critical - Retain",IF(AND(X56="High Value",S56<>"High Risk"),"High Value - Maintain",IF(AND(X56<>"High Value",S56="High Risk"),"At Risk - Develop","Stable"))) -> Stable | Z56: =IF(OR(B56<18,F56<0,N56<0,O56<0,O56>1,M56<0,M56>1),"Check Data","Valid") -> Check Data
A57: CUST_8989 | B57: 39 | C57: Other | D57: UK | E57: 64.39 | F57: 10 | G57: 39 | H57: 0 | I57: Beauty | J57: 24.2 | K57: 44751 | L57: 22 | M57: 0.4 | N57: =IF(E57="",Data_Validation!$B$1,E57) -> 64.39 | O57: =IF(J57="",Data_Validation!$B$2,J57) -> 24.2 | P57: =COUNTIF($A$2:$A$5001,A57) -> 1 | Q57: =CustomerData[[#This Row],[avg_order_value_clean]]*CustomerData[[#This Row],[total_orders]] -> 643.9 | R57: =IF(G57<=30,"Active",IF(G57<=90,"At Risk","Inactive")) -> At Risk | S57: =IF(M57<0.2,"Low Risk",IF(M57<0.5,"Medium Risk","High Risk")) -> Medium Risk | T57: =IF(B57<25,"Under 25",IF(B57<35,"25-34",IF(B57<45,"35-44",IF(B57<55,"45-54","55+")))) -> 35-44 | U57: =TODAY()-K57 -> 1510 | V57: =IF(L57<40,"Low Loyalty",IF(L57<70,"Medium Loyalty","High Loyalty")) -> Low Loyalty | W57: =IF(H57=1,"Fraudulent","Legitimate") -> Legitimate | X57: =IF(Q57<Data_Validation!$B$8,"Low Value",IF(Q57<Data_Validation!$B$9,"Medium Value","High Value")) -> Low Value | Y57: =IF(AND(X57="High Value",S57="High Risk"),"Critical - Retain",IF(AND(X57="High Value",S57<>"High Risk"),"High Value - Maintain",IF(AND(X57<>"High Value",S57="High Risk"),"At Risk - Develop","Stable"))) -> Stable | Z57: =IF(OR(B57<18,F57<0,N57<0,O57<0,O57>1,M57<0,M57>1),"Check Data","Valid") -> Check Data
A58: CUST_7873 | B58: 76 | C58: Male | D58: France | E58: 188.66 | F58: 19 | G58: 352 | H58: 0 | I58: Home | J58: 5.8 | K58: 45411 | L58: 62 | M58: 0.33 | N58: =IF(E58="",Data_Validation!$B$1,E58) -> 188.66 | O58: =IF(J58="",Data_Validation!$B$2,J58) -> 5.8 | P58: =COUNTIF($A$2:$A$5001,A58) -> 1 | Q58: =CustomerData[[#This Row],[avg_order_value_clean]]*CustomerData[[#This Row],[total_orders]] -> 3584.54 | R58: =IF(G58<=30,"Active",IF(G58<=90,"At Risk","Inactive")) -> Inactive | S58: =IF(M58<0.2,"Low Risk",IF(M58<0.5,"Medium Risk","High Risk")) -> Medium Risk | T58: =IF(B58<25,"Under 25",IF(B58<35,"25-34",IF(B58<45,"35-44",IF(B58<55,"45-54","55+")))) -> 55+ | U58: =TODAY()-K58 -> 850 | V58: =IF(L58<40,"Low Loyalty",IF(L58<70,"Medium Loyalty","High Loyalty")) -> Medium Loyalty | W58: =IF(H58=1,"Fraudulent","Legitimate") -> Legitimate | X58: =IF(Q58<Data_Validation!$B$8,"Low Value",IF(Q58<Data_Validation!$B$9,"Medium Value","High Value")) -> High Value | Y58: =IF(AND(X58="High Value",S58="High Risk"),"Critical - Retain",IF(AND(X58="High Value",S58<>"High Risk"),"High Value - Maintain",IF(AND(X58<>"High Value",S58="High Risk"),"At Risk - Develop","Stable"))) -> High Value - Maintain | Z58: =IF(OR(B58<18,F58<0,N58<0,O58<0,O58>1,M58<0,M58>1),"Check Data","Valid") -> Check Data
A59: CUST_6675 | B59: 77 | C59: Male | D59: Canada | E59: 142.52 | F59: 10 | G59: 201 | H59: 0 | I59: Home | J59: 4 | K59: 44389 | L59: 93 | M59: 0.31 | N59: =IF(E59="",Data_Validation!$B$1,E59) -> 142.52 | O59: =IF(J59="",Data_Validation!$B$2,J59) -> 4 | P59: =COUNTIF($A$2:$A$5001,A59) -> 3 | Q59: =CustomerData[[#This Row],[avg_order_value_clean]]*CustomerData[[#This Row],[total_orders]] -> 1425.2 | R59: =IF(G59<=30,"Active",IF(G59<=90,"At Risk","Inactive")) -> Inactive | S59: =IF(M59<0.2,"Low Risk",IF(M59<0.5,"Medium Risk","High Risk")) -> Medium Risk | T59: =IF(B59<25,"Under 25",IF(B59<35,"25-34",IF(B59<45,"35-44",IF(B59<55,"45-54","55+")))) -> 55+ | U59: =TODAY()-K59 -> 1872 | V59: =IF(L59<40,"Low Loyalty",IF(L59<70,"Medium Loyalty","High Loyalty")) -> High Loyalty | W59: =IF(H59=1,"Fraudulent","Legitimate") -> Legitimate | X59: =IF(Q59<Data_Validation!$B$8,"Low Value",IF(Q59<Data_Validation!$B$9,"Medium Value","High Value")) -> Low Value | Y59: =IF(AND(X59="High Value",S59="High Risk"),"Critical - Retain",IF(AND(X59="High Value",S59<>"High Risk"),"High Value - Maintain",IF(AND(X59<>"High Value",S59="High Risk"),"At Risk - Develop","Stable"))) -> Stable | Z59: =IF(OR(B59<18,F59<0,N59<0,O59<0,O59>1,M59<0,M59>1),"Check Data","Valid") -> Check Data
A60: CUST_1161 | B60: 36 | C60: Male | D60: Japan | F60: 12 | G60: 85 | H60: 0 | I60: Beauty | J60: 2.9 | K60: 44979 | L60: 45 | M60: 0.35 | N60: =IF(E60="",Data_Validation!$B$1,E60) -> 250 | O60: =IF(J60="",Data_Validation!$B$2,J60) -> 2.9 | P60: =COUNTIF($A$2:$A$5001,A60) -> 2 | Q60: =CustomerData[[#This Row],[avg_order_value_clean]]*CustomerData[[#This Row],[total_orders]] -> 3000 | R60: =IF(G60<=30,"Active",IF(G60<=90,"At Risk","Inactive")) -> At Risk | S60: =IF(M60<0.2,"Low Risk",IF(M60<0.5,"Medium Risk","High Risk")) -> Medium Risk | T60: =IF(B60<25,"Under 25",IF(B60<35,"25-34",IF(B60<45,"35-44",IF(B60<55,"45-54","55+")))) -> 35-44 | U60: =TODAY()-K60 -> 1282 | V60: =IF(L60<40,"Low Loyalty",IF(L60<70,"Medium Loyalty","High Loyalty")) -> Medium Loyalty | W60: =IF(H60=1,"Fraudulent","Legitimate") -> Legitimate | X60: =IF(Q60<Data_Validation!$B$8,"Low Value",IF(Q60<Data_Validation!$B$9,"Medium Value","High Value")) -> High Value | Y60: =IF(AND(X60="High Value",S60="High Risk"),"Critical - Retain",IF(AND(X60="High Value",S60<>"High Risk"),"High Value - Maintain",IF(AND(X60<>"High Value",S60="High Risk"),"At Risk - Develop","Stable"))) -> High Value - Maintain | Z60: =IF(OR(B60<18,F60<0,N60<0,O60<0,O60>1,M60<0,M60>1),"Check Data","Valid") -> Check Data
A61: CUST_5297 | B61: 79 | C61: Male | D61: Canada | E61: 78.1 | F61: 16 | G61: 42 | H61: 0 | I61: Sports | J61: 73.6 | K61: 45545 | L61: 11 | M61: 0.17 | N61: =IF(E61="",Data_Validation!$B$1,E61) -> 78.1 | O61: =IF(J61="",Data_Validation!$B$2,J61) -> 73.6 | P61: =COUNTIF($A$2:$A$5001,A61) -> 1 | Q61: =CustomerData[[#This Row],[avg_order_value_clean]]*CustomerData[[#This Row],[total_orders]] -> 1249.6 | R61: =IF(G61<=30,"Active",IF(G61<=90,"At Risk","Inactive")) -> At Risk | S61: =IF(M61<0.2,"Low Risk",IF(M61<0.5,"Medium Risk","High Risk")) -> Low Risk | T61: =IF(B61<25,"Under 25",IF(B61<35,"25-34",IF(B61<45,"35-44",IF(B61<55,"45-54","55+")))) -> 55+ | U61: =TODAY()-K61 -> 716 | V61: =IF(L61<40,"Low Loyalty",IF(L61<70,"Medium Loyalty","High Loyalty")) -> Low Loyalty | W61: =IF(H61=1,"Fraudulent","Legitimate") -> Legitimate | X61: =IF(Q61<Data_Validation!$B$8,"Low Value",IF(Q61<Data_Validation!$B$9,"Medium Value","High Value")) -> Low Value | Y61: =IF(AND(X61="High Value",S61="High Risk"),"Critical - Retain",IF(AND(X61="High Value",S61<>"High Risk"),"High Value - Maintain",IF(AND(X61<>"High Value",S61="High Risk"),"At Risk - Develop","Stable"))) -> Stable | Z61: =IF(OR(B61<18,F61<0,N61<0,O61<0,O61>1,M61<0,M61>1),"Check Data","Valid") -> Check Data
A62: CUST_1995 | B62: 64 | C62: Female | D62: France | E62: 29.96 | F62: 10 | G62: 235 | H62: 0 | I62: Electronics | J62: 34.2 | K62: 45082 | L62: 33 | M62: 0.38 | N62: =IF(E62="",Data_Validation!$B$1,E62) -> 29.96 | O62: =IF(J62="",Data_Validation!$B$2,J62) -> 34.2 | P62: =COUNTIF($A$2:$A$5001,A62) -> 1 | Q62: =CustomerData[[#This Row],[avg_order_value_clean]]*CustomerData[[#This Row],[total_orders]] -> 299.6 | R62: =IF(G62<=30,"Active",IF(G62<=90,"At Risk","Inactive")) -> Inactive | S62: =IF(M62<0.2,"Low Risk",IF(M62<0.5,"Medium Risk","High Risk")) -> Medium Risk | T62: =IF(B62<25,"Under 25",IF(B62<35,"25-34",IF(B62<45,"35-44",IF(B62<55,"45-54","55+")))) -> 55+ | U62: =TODAY()-K62 -> 1179 | V62: =IF(L62<40,"Low Loyalty",IF(L62<70,"Medium Loyalty","High Loyalty")) -> Low Loyalty | W62: =IF(H62=1,"Fraudulent","Legitimate") -> Legitimate | X62: =IF(Q62<Data_Validation!$B$8,"Low Value",IF(Q62<Data_Validation!$B$9,"Medium Value","High Value")) -> Low Value | Y62: =IF(AND(X62="High Value",S62="High Risk"),"Critical - Retain",IF(AND(X62="High Value",S62<>"High Risk"),"High Value - Maintain",IF(AND(X62<>"High Value",S62="High Risk"),"At Risk - Develop","Stable"))) -> Stable | Z62: =IF(OR(B62<18,F62<0,N62<0,O62<0,O62>1,M62<0,M62>1),"Check Data","Valid") -> Check Data
A63: CUST_8629 | B63: 79 | C63: Female | D63: China | E63: 25.66 | F63: 12 | G63: 69 | H63: 0 | I63: Beauty | J63: 82.4 | K63: 44301 | L63: 38 | M63: 0.33 | N63: =IF(E63="",Data_Validation!$B$1,E63) -> 25.66 | O63: =IF(J63="",Data_Validation!$B$2,J63) -> 82.4 | P63: =COUNTIF($A$2:$A$5001,A63) -> 2 | Q63: =CustomerData[[#This Row],[avg_order_value_clean]]*CustomerData[[#This Row],[total_orders]] -> 307.92 | R63: =IF(G63<=30,"Active",IF(G63<=90,"At Risk","Inactive")) -> At Risk | S63: =IF(M63<0.2,"Low Risk",IF(M63<0.5,"Medium Risk","High Risk")) -> Medium Risk | T63: =IF(B63<25,"Under 25",IF(B63<35,"25-34",IF(B63<45,"35-44",IF(B63<55,"45-54","55+")))) -> 55+ | U63: =TODAY()-K63 -> 1960 | V63: =IF(L63<40,"Low Loyalty",IF(L63<70,"Medium Loyalty","High Loyalty")) -> Low Loyalty | W63: =IF(H63=1,"Fraudulent","Legitimate") -> Legitimate | X63: =IF(Q63<Data_Validation!$B$8,"Low Value",IF(Q63<Data_Validation!$B$9,"Medium Value","High Value")) -> Low Value | Y63: =IF(AND(X63="High Value",S63="High Risk"),"Critical - Retain",IF(AND(X63="High Value",S63<>"High Risk"),"High Value - Maintain",IF(AND(X63<>"High Value",S63="High Risk"),"At Risk - Develop","Stable"))) -> Stable | Z63: =IF(OR(B63<18,F63<0,N63<0,O63<0,O63>1,M63<0,M63>1),"Check Data","Valid") -> Check Data
...

Sheet Data_Validation
A1: avg_order_value | B1: =COUNTBLANK(CustomerData[avg_order_value]) -> 250
A2: email_open_rate | B2: =COUNTBLANK(CustomerData[email_open_rate]) -> 250
A3: Median Average Order Value | B3: =MEDIAN(CustomerData[avg_order_value]) -> 93.19
A4: Median Email Open Rate | B4: =MEDIAN(CustomerData[email_open_rate]) -> 50.95
A7: Q1 Customer Value | B7: =_xlfn.PERCENTILE.INC(Cleaned_Data!$Q$2:$Q$5001,0.25) -> 543.85
A8: Q3 Customer Value | B8: =_xlfn.PERCENTILE.INC(Cleaned_Data!$Q$2:$Q$5001,0.75) -> 1525.975

Sheet Excel_Analysis
A3: Row Labels | B3: Count of customer_id | D3: Row Labels | E3: Sum of churn_risk
A4: At Risk - Develop | B4: 419 | D4: Active | E4: 114.54
A5: Critical - Retain | B5: 138 | D5: At Risk | E5: 243.66
A6: High Value - Maintain | B6: 1112 | D6: Inactive | E6: 1064.22
A7: Stable | B7: 3331 | D7: Grand Total | E7: 1422.42
A8: Grand Total | B8: 5000
A11: Row Labels | B11: Sum of estimated_customer_value | D11: Row Labels | E11: Average of churn_risk
A12: Australia | B12: 600556.32 | D12: High Loyalty | E12: 0.28435348
A13: Brazil | B13: 611514.63 | D13: Low Loyalty | E13: 0.28306761
A14: Canada | B14: 584673.56 | D14: Medium Loyalty | E14: 0.28651792
A15: China | B15: 564465.24 | D15: Grand Total | E15: 0.284484
A16: France | B16: 549144.39
A17: Germany | B17: 581605.71
A18: India | B18: 624555.8
A19: Japan | B19: 548197.03 | D19: Row Labels | E19: Average of estimated_customer_value | F19: Count of customer_id
A20: UK | B20: 547793.96 | D20: Fraudulent | E20: 1092.4355 | F20: 129
A21: USA | B21: 615782.85 | D21: Legitimate | E21: 1167.5971 | F21: 4871
A22: Grand Total | B22: 5828289.5 | D22: Grand Total | E22: 1165.6579 | F22: 5000
